<?xml version="1.0" encoding="utf-8"?>
<!-- This URDF was automatically created by SolidWorks to URDF Exporter! Originally created by Stephen Brawner (brawner@gmail.com) 
     Commit Version: 1.5.1-0-g916b5db  Build Version: 1.5.7152.31018
     For more information, please see http://wiki.ros.org/sw_urdf_exporter -->
<robot name="arm">
  <link name="base_link">
    <inertial>
    <origin
      xyz="0 0 0"
      rpy="0 0 0" />
      <mass
        value="0.21489" />
      <inertia
        ixx="0.00012386"
        ixy="8.4891E-10"
        ixz="-4.4752E-07"
        iyy="0.00011773"
        iyz="-2.3379E-11"
        izz="0.00014456" />
    </inertial>
    <visual>
      <origin
        xyz="0 0 0"
        rpy="0 0 0" />
      <geometry>
        <mesh
          filename="package://icrp_urdf/meshes/co602_490/base_link.STL" />
      </geometry>
      <material name="">
        <color
          rgba="0.75294 0.75294 0.75294 1" />
      </material>
    </visual>
    <collision>
      <origin
        xyz="0 0 0"
        rpy="0 0 0" />
      <geometry>
        <mesh
          filename="package://icrp_urdf/meshes/co602_490/base_link.STL" />
      </geometry>
    </collision>
  </link>
  <link name="link1">
    <inertial>
    <origin
      xyz="0 0 0"
      rpy="0 0 0" />
      <mass
        value="0.28474" />
      <inertia
        ixx="0.00013194"
        ixy="-1.7444E-09"
        ixz="-1.1686E-05"
        iyy="0.00013718"
        iyz="6.4557E-10"
        izz="0.00013887" />
    </inertial>
    <visual>
      <origin
        xyz="0 0 -0.125"
        rpy="0 0 3.14" />
      <geometry>
        <mesh
          filename="package://icrp_urdf/meshes/co602_490/link1.STL" />
      </geometry>
      <material
        name="">
        <color
          rgba="0.75294 0.75294 0.75294 1" />
      </material>
    </visual>
    <collision>
      <origin
        xyz="0 0 -0.125"
        rpy="0 0 3.14" />
      <geometry>
        <mesh
          filename="package://icrp_urdf/meshes/co602_490/link1.STL" />
      </geometry>
    </collision>
  </link>
  <joint name="joint_1" type="revolute">
    <origin
      xyz="0 0 0.125"
      rpy="0 0 0" />
    <parent
      link="base_link" />
    <child
      link="link1" />
    <axis
      xyz="0 0 1" />
    <limit
      lower="-3"
      upper="3"
      effort="0"
      velocity="0" />
  </joint>
  <link name="link2">
    <inertial>
    <origin
      xyz="0 0 0"
      rpy="0 0 0" />
      <mass
        value="0.89644" />
      <inertia
        ixx="0.0007066"
        ixy="1.2001E-09"
        ixz="8.4306E-20"
        iyy="0.00040071"
        iyz="8.4495E-21"
        izz="0.00070392" />
    </inertial>
    <visual>
      <origin
        xyz="-0.125 0 0.0965"
        rpy="-1.57 0 -1.57" />
      <geometry>
        <mesh
          filename="package://icrp_urdf/meshes/co602_490/link2.STL" />
      </geometry>
      <material
        name="">
        <color
          rgba="0.75294 0.75294 0.75294 1" />
      </material>
    </visual>
    <collision>
      <origin
        xyz="-0.125 0 0.0965"
        rpy="-1.57 0 -1.57" />
      <geometry>
        <mesh
          filename="package://icrp_urdf/meshes/co602_490/link2.STL" />
      </geometry>
    </collision>
  </link>
  <joint  name="joint_2" type="revolute">
    <origin
      xyz="0 -0.0965 0"
      rpy="-1.57 0 0" />
    <parent
      link="link1" />
    <child
      link="link2" />
    <axis
      xyz="0 0 1" />
    <limit
      lower="-2.09"
      upper="2.09"
      effort="0"
      velocity="0" />
  </joint>
  <link  name="link3">
	<inertial>
    <origin
      xyz="0 0 0"
      rpy="0 0 0" />
      <mass
        value="0.47145" />
      <inertia
        ixx="0.00023614"
        ixy="9.9301E-10"
        ixz="-2.3681E-09"
        iyy="0.00013622"
        iyz="7.8682E-06"
        izz="0.0002462" />
    </inertial>
    <visual>
      <origin
        xyz="-0.345 0 0.0965"
        rpy="-1.57 0 -1.57" />
      <geometry>
        <mesh
          filename="package://icrp_urdf/meshes/co602_490/link3.STL" />
      </geometry>
      <material
        name="">
        <color
          rgba="0.75294 0.75294 0.75294 1" />
      </material>
    </visual>
    <collision>
      <origin
        xyz="-0.345 0 0.0965"
        rpy="-1.57 0 -1.57" />
      <geometry>
        <mesh
          filename="package://icrp_urdf/meshes/co602_490/link3.STL" />
      </geometry>
    </collision>
  </link>
  <joint name="joint_3" type="revolute">
    <origin
      xyz="0.22 0 0"
      rpy="0 0 0" />
    <parent
      link="link2" />
    <child
      link="link3" />
    <axis
      xyz="0 0 1" />
    <limit
      lower="-2.6"
      upper="2.6"
      effort="0"
      velocity="0" />
  </joint>
  <link name="link4">
    <inertial>
    <origin
      xyz="0 0 0"
      rpy="0 0 0" />
      <mass
        value="0.13771" />
      <inertia
        ixx="3.9936E-05"
        ixy="7.1527E-11"
        ixz="3.1643E-10"
        iyy="4.3211E-05"
        iyz="3.3237E-06"
        izz="3.8225E-05" />
    </inertial>
    <visual>
      <origin
        xyz="0 -0.5365 0.0015"
        rpy="-1.57 0 0" />
      <geometry>
        <mesh
          filename="package://icrp_urdf/meshes/co602_490/link4.STL" />
      </geometry>
      <material
        name="">
        <color
          rgba="0.75294 0.75294 0.75294 1" />
      </material>
    </visual>
    <collision>
      <origin
        xyz="0 -0.5365 0.0015"
        rpy="-1.57 0 0" />
      <geometry>
        <mesh
          filename="package://icrp_urdf/meshes/co602_490/link4.STL" />
      </geometry>
    </collision>
  </link>
  <joint name="joint_4" type="revolute">
    <origin
      xyz="0.1915 0 0.095"
      rpy="0 0 0" />
    <parent
      link="link3" />
    <child
      link="link4" />
    <axis
      xyz="0 0 1" />
    <limit
      lower="-3"
      upper="3"
      effort="0"
      velocity="0" />
  </joint>
  <link name="link5">
    <inertial>
    <origin
      xyz="0 0 0"
      rpy="0 0 0" />
      <mass
        value="0.13771" />
      <inertia
        ixx="4.3211E-05"
        ixy="-7.2359E-11"
        ixz="-3.3237E-06"
        iyy="3.9935E-05"
        iyz="-4.3362E-10"
        izz="3.8225E-05" />
    </inertial>
    <visual>
      <origin
        xyz="0 -0.080 0.5365"
        rpy="3.14 0 3.14" />
      <geometry>
        <mesh
          filename="package://icrp_urdf/meshes/co602_490/link5.STL" />
      </geometry>
      <material
        name="">
        <color
          rgba="0.75294 0.75294 0.75294 1" />
      </material>
    </visual>
    <collision>
      <origin
        xyz="0 -0.080 0.5365"
        rpy="3.14 0 3.14" />
      <geometry>
        <mesh
          filename="package://icrp_urdf/meshes/co602_490/link5.STL" />
      </geometry>
    </collision>
  </link>
  <joint name="joint_5" type="revolute">
    <origin
      xyz="0 0 -0.0785"
      rpy="1.57 0 0" />
    <parent
      link="link4" />
    <child
      link="link5" />
    <axis
      xyz="0 0 1" />
    <limit
      lower="-3"
      upper="3"
      effort="0"
      velocity="0" />
  </joint>
  <link name="link6">
	<inertial>
    <origin
      xyz="0 0 0"
      rpy="0 0 0" />
      <mass
        value="0.052428" />
      <inertia
        ixx="1.2291E-05"
        ixy="5.4308E-08"
        ixz="-3.9338E-07"
        iyy="1.2524E-05"
        iyz="-2.2177E-07"
        izz="1.4037E-05" />
    </inertial>
    <visual>
      <origin
        xyz="0 -0.615 -0.080"
        rpy="1.57 0 -3.14" />
      <geometry>
        <mesh
          filename="package://icrp_urdf/meshes/co602_490/link6.STL" />
      </geometry>
      <material
        name="">
        <color
          rgba="0.75294 0.75294 0.75294 1" />
      </material>
    </visual>
    <collision>
      <origin
        xyz="0 -0.615 -0.080"
        rpy="1.57 0 -3.14" />
      <geometry>
        <mesh
          filename="package://icrp_urdf/meshes/co602_490/link6.STL" />
      </geometry>
    </collision>
  </link>
  <joint name="joint_6" type="revolute">
    <origin
      xyz="0 0 -0.0785"
      rpy="-1.57 0 0" />
    <parent
      link="link5" />
    <child
      link="link6" />
    <axis
      xyz="0 0 1" />
    <limit
      lower="-3.0"
      upper="3.0"
      effort="0"
      velocity="0" />
  </joint>
   <link name="gripper">
    <visual>
      <origin rpy="0 0 0" xyz="0 0 0"/>
      <geometry>
  	<box size="0.001 0.0005 0.0005"/>
      </geometry>
      <material name="">
        <color rgba="0.75294 0.75294 0.75294 1"/>
      </material>
    </visual>
    <collision>
      <origin rpy="0 0 0" xyz="0 0 0"/>
      <geometry>
       <box size="0.001 0.0005 0.0005"/>
      </geometry>
    </collision>
  </link>
  <joint name="gripper_robot_joint" type="fixed">
    <parent link="link6"/>
    <child link="gripper"/>
    <origin rpy="0 0 0" xyz="0.0 0 0.0"/>
  </joint>
  
  <link name="pick_gripper_link">
    <visual>
      <origin rpy="0 0 0" xyz="0 0 0"/>
      <geometry>
        <box size="0.001 0.0005 0.0005"/>
      </geometry>
    </visual>
  </link>

  <joint name="pick_gripper_joint" type="fixed">

    <origin rpy="0 0 0" xyz="0 0 0"/>

    <axis xyz="0 0 1"/>
    <parent link="gripper"/>
    <child link="pick_gripper_link"/>
  </joint>
  
</robot>
